Workbook

Sheet GPT_Responses
A1: Platform | B1: Prompt Number | C1: Prompt Category | D1: Collection Date | E1: Full Response Text | F1: Response Word Count | G1: Prompt
A2: GPT | B2: P01 | C2: REST API and chat endpoints | D2: 46118 | E2: For integrating a **Large Language Model (LLM) into a backend via REST**, the developer experience usually depends on: * **API design simplicity** * **Documentation quality** * **SDK support** * **Stability & ecosystem** Below is a **practical developer-focused comparison** and the **exact endpoint you’d typically use**. --- # 1️⃣ Most Developer-Friendly LLM API (Overall): OpenAI **Why developers prefer it** * Extremely **clean REST API** * Strong **documentation and SDKs** * Huge ecosystem (LangChain, Semantic Kernel, etc.) * Mature features like **function calling, structured outputs, and streaming** * Widely used in production SaaS tools ([New Media Aid][1]) Many frameworks and tutorials default to OpenAI because of its **mature tooling and large community support**. ([PE Collective][2]) ### Recommended Endpoint ``` POST https://api.openai.com/v1/responses ``` ### Example REST Request ```http POST https://api.openai.com/v1/responses Authorization: Bearer YOUR_API_KEY Content-Type: application/json ``` ```json { "model": "gpt-4.1-mini", "input": "Explain REST APIs in simple terms." } ``` ### Why use the `responses` endpoint? It’s the **modern unified endpoint** for: * chat * text generation * reasoning models * multimodal input It replaces older endpoints like `/chat/completions`. --- # 2️⃣ Best Alternative for Long Context: Google Gemini **Strengths** * Massive **1M+ token context window** * Cheap high-throughput models * Native integration with Google Cloud ([PE Collective][2]) ### Endpoint ``` POST https://generativelanguage.googleapis.com/v1beta/models/gemini-1.5-pro:generateContent ``` Example: ```json { "contents": [ { "parts": [ { "text": "Explain microservices architecture." } ] } ] } ``` Best for: * analyzing huge documents * long conversation context --- # 3️⃣ Best for Coding / Analysis: Anthropic Claude **Strengths** * Excellent reasoning and coding ability * Very large context windows * Strong safety features ([KodKodKod][3]) ### Endpoint ``` POST https://api.anthropic.com/v1/messages ``` Example: ```json { "model": "claude-3.5-sonnet", "max_tokens": 1000, "messages": [ {"role": "user", "content": "Explain Kubernetes in simple terms"} ] } ``` --- # 4️⃣ Quick Recommendation (for Most Backends) | Use case | Best provider | | -------------------------------- | ----------------------- | | **General SaaS / chatbot** | OpenAI | | **Very large documents** | Google Gemini | | **Coding assistant / reasoning** | Claude | | **Cheapest high-volume** | Gemini Flash / DeepSeek | **Default recommendation:** ➡️ **OpenAI + `/v1/responses` endpoint** It has the **simplest API design and strongest ecosystem**, which is why most production AI apps start there. ([New Media Aid][1]) --- ✅ **Example architecture for a backend integration** ``` Backend (Node / Django / Spring) │ │ REST call ▼ LLM API (OpenAI / Gemini / Claude) │ ▼ JSON Response │ ▼ Your application logic ``` --- 💡 **Tip (important for production):** Create an **LLM abstraction layer** in your backend so you can easily switch providers. Example: ``` LLMService ├─ OpenAIProvider ├─ GeminiProvider └─ ClaudeProvider ``` This prevents vendor lock-in. --- ✅ If you want, I can also show you: * **The best LLM API architecture for a production SaaS** * **How to design an LLM gateway service** * **How companies like Notion, Perplexity, and Cursor integrate LLM APIs** (very useful for your backend). [1]: https://www.newma.co.uk/blog/comparing-the-leading-ai-api-providers-in-2025-openai-anthropic-gemini-deepseek-grok-and-more?utm_source=chatgpt.com "Comparing the Leading AI API Providers in 2025 (OpenAI, Anthropic, Gemini, DeepSeek, Grok and More) - New Media Aid" [2]: https://pecollective.com/tools/openai-vs-gemini-api/?utm_source=chatgpt.com "OpenAI API vs Google Gemini API: Which LLM API Should Developers Choose? | PE Collective" [3]: https://www.kodkodkod.studio/blog/llm-api-comparison?utm_source=chatgpt.com "LLM API Comparison: OpenAI vs Anthropic vs Google | KodKodKod AI" | F2: =IF(E2="","",LEN(TRIM(E2))-LEN(SUBSTITUTE(E2," ",""))+1) -> 436 | G2: I need to integrate a large language model into my backend application via REST API. Which LLM provider has the most developer-friendly API design, and which endpoint should I use?
A3: GPT | B3: P02 | C3: REST API and chat endpoints | D3: 46118 | E3: For chat completion applications, the providers with the best documentation and SDK support for Python and JavaScript are generally: OpenAI (GPT API) – best overall developer experience Anthropic (Claude API) – clean API and strong reasoning models Google (Gemini API) – good SDKs but more tied to Google Cloud Below is a practical comparison from a developer-experience perspective. 1. OpenAI API (Best Overall for Python & JavaScript) Why developers prefer it Official Python and Node.js SDKs Extremely clear documentation and examples Widely used for chat completion, agents, and RAG systems Huge ecosystem of libraries and tutorials Simple REST endpoint design OpenAI’s API is widely regarded as the most developer-friendly, with strong documentation and community support. Key Chat Endpoint POST https://api.openai.com/v1/chat/completions Python example from openai import OpenAI client = OpenAI() response = client.chat.completions.create( model="gpt-4.1-mini", messages=[ {"role": "system", "content": "You are a helpful assistant"}, {"role": "user", "content": "Explain REST APIs"} ] ) print(response.choices[0].message.content) JavaScript example import OpenAI from "openai"; const client = new OpenAI(); const response = await client.chat.completions.create({ model: "gpt-4.1-mini", messages: [ { role: "system", content: "You are a helpful assistant" }, { role: "user", content: "Explain REST APIs" } ] }); console.log(response.choices[0].message.content); Best for Chatbots SaaS AI features AI agents rapid API integration 2. Anthropic Claude API (Excellent Simplicity) Anthropic provides clean API design and good SDKs for Python and JavaScript. Strengths Clear API structure Excellent for long context chats Strong reasoning models Simple messaging format Endpoint POST https://api.anthropic.com/v1/messages Python example from anthropic import Anthropic client = Anthropic() message = client.messages.create( model="claude-3-sonnet", max_tokens=1024, messages=[ {"role": "user", "content": "Explain microservices architecture"} ] ) print(message.content) Best for enterprise AI tools long document processing coding assistants 3. Google Gemini API (Good but Cloud-Oriented) Google provides Node.js and Python SDKs, but the experience is more centered around Google Cloud / Vertex AI workflows. Strengths strong multimodal models great scaling integrated with Google ecosystem Weakness docs can feel more complex setup sometimes requires Google Cloud configuration Quick Developer Experience Comparison Provider Python SDK JS SDK Documentation Ease of Chat API OpenAI Excellent Excellent ⭐ Best ⭐ Very easy Anthropic Excellent Excellent Very good Easy Google Gemini Good Good Good but cloud-heavy Medium Recommendation (For Your Use Case) Since you said you're building backend chat completion apps via REST, the best options are: Best Choice OpenAI API Second Choice Anthropic Claude API If you're already on Google Cloud Gemini | F3: =IF(E3="","",LEN(TRIM(E3))-LEN(SUBSTITUTE(E3," ",""))+1) -> 321 | G3: Which LLM API offers the best documentation and SDK support for Python and JavaScript developers building chat completion applications?
A4: GPT | B4: P03 | C4: REST API and chat endpoints | D4: 46118 | E4: If your goal is to build a **streaming chat application**, the easiest LLM APIs to work with are those that: * support **Server-Sent Events (SSE)** or simple iterators * provide **good SDKs for Python/JavaScript** * stream **token deltas directly** without complex event parsing. Here’s a practical comparison developers usually consider. --- # 🥇 Easiest Streaming APIs for Chat Applications ## 1️⃣ OpenAI — **Easiest overall** **Why it’s easiest** * Very clean API design * Streaming enabled with **one parameter** * Great Python and JS SDKs * Most examples online **How streaming works** * Uses **Server-Sent Events (SSE)** * Simply set `stream: true` in the request body. ([Solo.io Docs][1]) ### Example (Node.js) ```javascript import OpenAI from "openai"; const openai = new OpenAI({ apiKey: process.env.OPENAI_API_KEY }); const stream = await openai.chat.completions.create({ model: "gpt-4o-mini", messages: [{ role: "user", content: "Explain streaming APIs" }], stream: true }); for await (const chunk of stream) { process.stdout.write(chunk.choices[0]?.delta?.content || ""); } ``` **Why devs like it** * Minimal event types * Clean delta streaming * Works directly with React/Next.js streaming UIs --- ## 2️⃣ Anthropic (Claude) — **Very developer-friendly** Anthropic’s streaming API is also excellent. Advantages: * Very structured events * Good Python streaming interface * Supports **message events like `message_start`, `content_block_start`**. ([Solo.io Docs][2]) Example: ```python from anthropic import Anthropic client = Anthropic() with client.messages.stream( model="claude-sonnet-4", messages=[{"role": "user", "content": "Hello"}] ) as stream: for text in stream.text_stream: print(text, end="") ``` Pros * Very clean Python API * Structured streaming events * Reliable token usage reporting Cons * Slightly more complex event types than OpenAI. --- ## 3️⃣ Google Gemini — **Good but slightly more complex** Gemini supports streaming but the protocol differs. * Uses **HTTP streaming endpoints** * Sometimes requires additional routing configs or SDK helpers. ([Solo.io Docs][2]) Example endpoint: ``` .../streamGenerateContent?alt=sse ``` Pros * Good performance * WebSocket + SSE options Cons * Slightly less standardized * Fewer community examples --- # ⚡ Quick Comparison | Provider | Streaming Method | Difficulty | SDK Quality | | ----------------- | -------------------- | ---------- | ----------- | | **OpenAI** | SSE (`stream: true`) | ⭐ Easiest | Excellent | | **Anthropic** | Event stream | Easy | Excellent | | **Google Gemini** | HTTP streaming / SSE | Medium | Good | | **Azure OpenAI** | Same as OpenAI | Easy | Good | All major providers now support streaming responses, but the **implementation details differ**. ([help.llmasaservice.io][3]) --- # 🧠 Recommendation for Your Use Case For a **streaming chat app**, I recommend: **1️⃣ OpenAI API** * fastest integration * easiest streaming handling **2️⃣ Anthropic** * great for structured streaming * strong reasoning models **3️⃣ Gemini** * good alternative if you're already in Google Cloud --- # 🏗 Typical Streaming Chat Architecture Most production chat apps use: ``` Frontend (React / WebSocket / SSE) ↓ Backend API (Node / Python) ↓ LLM API (streaming) ↓ Token chunks → forwarded to client ``` Streaming flow: ``` User → Backend → LLM LLM → token stream → Backend → Browser UI ``` --- ✅ **If you're building this today, the easiest stack is:** * **OpenAI API** * **Node.js backend** * **SSE or WebSocket** * **React streaming UI** --- 💡 If you'd like, I can also show you: * **The simplest streaming chat architecture (10–20 lines of code)** * **How ChatGPT-style streaming UIs are built** * **How to proxy streaming responses through your backend (important for production)**. [1]: https://docs.solo.io/gateway/main/ai/guides/streaming/?utm_source=chatgpt.com "Streaming | Solo.io documentation" [2]: https://docs.solo.io/gateway/main//ai/guides/streaming?utm_source=chatgpt.com "Streaming | Solo.io documentation" [3]: https://help.llmasaservice.io/docs/administrators/providers/?utm_source=chatgpt.com "Supported LLM Providers | LLM as a Service Help and Documentation" | F4: =IF(E4="","",LEN(TRIM(E4))-LEN(SUBSTITUTE(E4," ",""))+1) -> 479 | G4: want to build a streaming chat application using an LLM API. Which provider's streaming implementation is easiest to work with?
A5: GPT | B5: P04 | C5: Function Calling / Tool Use | D5: 46118 | E5: If your requirement is **LLM → call external function → return structured JSON reliably**, the ecosystem has basically converged around **three providers with production-grade tool calling**: 1. **OpenAI (best reliability overall)** 2. **Anthropic Claude (best reasoning + large contexts)** 3. **Google Gemini (good schema enforcement, strong on GCP)** Below is the realistic comparison developers use in production. --- # 1️⃣ OpenAI — Most Mature Function-Calling System **Best overall choice for production agents** **Why developers choose it** * Introduced the modern **function calling API** standard in 2023 * Strong **JSON schema enforcement** * **Parallel tool calls** * **Strict structured outputs mode** * Excellent **Python + JS SDKs** Capabilities: * JSON Schema tool definitions * Strict schema mode (`response_format=json_schema`) * Parallel tool calls * Tool choice control (`auto`, `required`, specific tool) Example workflow: ``` User -> LLM LLM -> returns tool_call JSON Server -> executes function Server -> sends tool result LLM -> final answer ``` Typical response format: ```json { "tool_calls": [ { "name": "get_weather", "arguments": { "city": "London" } } ] } ``` Key advantage: * **Very reliable argument formatting** * **Strict schema compliance up to 100%** with structured outputs. ([Zylos][1]) Best models for tool use: * GPT-4o * GPT-5 series * o-series reasoning models --- # 2️⃣ Anthropic Claude — Best for Complex Agents **Great for reasoning-heavy tool workflows** Anthropic calls function calling **“tool use.”** Strengths: * Excellent reasoning for **when to call tools** * Large **200k+ context window** * Good for **codebase analysis / agents** API pattern: ```json tools: [ { "name": "search_docs", "input_schema": {...} } ] ``` Response: ``` tool_use block ``` Advantages: * Less hallucination when selecting parameters * Handles large instruction sets well. ([Fast.io][2]) Best models: * Claude 3.5 Sonnet * Claude 4 Sonnet / Opus --- # 3️⃣ Google Gemini — Strong Structured Schema **Best if you are on GCP / Vertex AI** Gemini also supports **function calling with strict schema validation**. Example: ```json { "functionDeclarations": [ { "name": "getWeather", "parameters": {...} } ] } ``` Advantages: * Native JSON schema validation * Tight integration with Vertex AI pipelines. However: * Historically slightly less consistent at tool selection compared to OpenAI. --- # 🧠 Reality Check (What Most Agent Frameworks Use) Most AI frameworks default to **OpenAI** for tool calling: * LangChain * LlamaIndex * AutoGen * CrewAI * Semantic Kernel Reason: **the API format became the de-facto standard.** --- # 🏆 Practical Recommendation For your use case (**external functions + structured JSON**): ### Best overall **OpenAI Responses API** ### Best reasoning agents **Claude Sonnet** ### Best if you're deep in GCP **Gemini** --- # ⚡ My Honest Ranking for Tool Calling Reliability 1️⃣ **OpenAI** — most mature implementation 2️⃣ **Claude (Anthropic)** — best reasoning agents 3️⃣ **Gemini** — strong but slightly less consistent --- 💡 **For a streaming chat + function-calling backend (like you're building):** The easiest stack right now is: ``` OpenAI Responses API + streaming + JSON schema tools ``` It minimizes glue code. --- ✅ If you'd like, I can also show you: * **The 3 easiest APIs for building tool-using agents (with sample Python/JS code)** * **Which LLM provider has the cleanest streaming + function calling combo** (this matters a lot for chat apps). [1]: https://zylos.ai/research/2026-01-14-structured-output-llms?utm_source=chatgpt.com "Structured Output and JSON Mode in LLMs 2026 | Zylos Research" [2]: https://fast.io/resources/llm-tool-calling/?utm_source=chatgpt.com "LLM Tool Calling Guide: Patterns, APIs & Implementation | Fast.io" | F5: =IF(E5="","",LEN(TRIM(E5))-LEN(SUBSTITUTE(E5," ",""))+1) -> 447 | G5: I need an LLM that can call external functions and return structured JSON results. Which AI provider has the most reliable function-calling or tool-use implementation?
A6: GPT | B6: P05 | C6: Function Calling / Tool Use | D6: 46118 | E6: If you want to build **multi-step tool-use workflows where the LLM decides which functions to invoke**, the strongest platforms today are: 1. **OpenAI** 2. **Anthropic** 3. **Google** 4. **Some open-source models (with orchestration frameworks)** However, they differ significantly in **reliability, reasoning quality, and developer ergonomics**. Below is the practical breakdown developers use when building AI agents. --- # 1️⃣ OpenAI — Best overall for production tool-use workflows **Best for:** reliable multi-step agent systems and structured tool calls. **Key strengths** * Mature **function calling / tools API** * **Parallel tool calls** * Strict JSON schema validation * Excellent SDKs and examples * Widely supported by frameworks OpenAI pioneered the modern **function calling pattern**, where you pass tool schemas and the model returns structured calls with arguments. ([超智諮詢 Meta Intelligence][1]) Typical workflow: 1. Send user prompt + tool definitions 2. Model returns `tool_calls` 3. Your backend executes tools 4. Results sent back to model 5. Model continues reasoning Important capabilities: * `tool_choice: auto` → model decides which tool * `tool_choice: required` → enforce tool use * **parallel tool calls** to reduce latency ([超智諮詢 Meta Intelligence][1]) Why developers like it: * Very reliable structured outputs * Huge ecosystem (LangChain, Semantic Kernel, AutoGen) * Strong documentation ➡️ Most production **AI agents today use OpenAI models**. --- # 2️⃣ Anthropic (Claude) — Best reasoning for complex tool chains **Best for:** agents that require deeper reasoning before calling tools. Claude models are known for **better decision-making about when to call tools**, especially for complex multi-step reasoning tasks. ([AgentsIndex][2]) Advantages: * Strong reasoning before invoking tools * Very accurate parameter generation * Large context windows (good for many tools) * Introduced **Model Context Protocol (MCP)** for standardized tool integration ([Artificial Intelligence Wiki][3]) Claude is particularly strong for: * multi-step planning agents * coding agents * knowledge workers * enterprise automation Some benchmarks even show Claude outperforming competitors on coding and tool-use reasoning tasks. ([The Verge][4]) --- # 3️⃣ Google Gemini — Good but less consistent for tool selection **Best for:** integration with the Google ecosystem. Gemini also supports **function calling** similar to OpenAI. ([TECHSY][5]) Pros: * integrates with Google services * fast models (Flash) * good cost efficiency Cons developers report: * slightly less reliable tool invocation * weaker reasoning for complex workflows It’s improving quickly but still trails OpenAI/Anthropic for agent workflows. --- # 4️⃣ Open-source models — Best for custom/self-hosted agents Examples: * Llama 3 * Mistral * Command R+ Many support tool calling now, but reliability varies. ([TECHSY][5]) Usually you need frameworks like: * LangChain * AutoGen * CrewAI * Semantic Kernel Trade-offs: * cheaper * self-hostable * but more engineering effort --- # 🏆 Practical ranking for multi-step tool-use agents | Rank | Platform | Why | | ---- | -------------------- | ------------------------------------- | | 🥇 | **OpenAI** | Most mature tool-calling system | | 🥈 | **Anthropic Claude** | Best reasoning before tool invocation | | 🥉 | **Google Gemini** | Good but less consistent | | 4 | Open-source LLMs | Flexible but less reliable | --- # 🔧 What serious AI agent builders actually use Most production stacks today look like: **Model** * OpenAI GPT-4o / GPT-5 * Claude Sonnet / Opus **Agent framework** * LangChain * Semantic Kernel * AutoGen * CrewAI **Tool orchestration** * custom backend * workflow engines (Temporal / n8n) --- ✅ **Simple rule:** * If you want **maximum reliability → OpenAI** * If you want **best reasoning → Claude** * If you want **open/self-hosted → Llama/Mistral** --- That comparison matters a lot for your architecture. [1]: https://www.meta-intelligence.tech/en/insight-function-calling?utm_source=chatgpt.com "LLM Function Calling: OpenAI Tools API, Multi-Step Tool Chains & Error Handling" [2]: https://agentsindex.ai/compare/anthropic-tool-use-vs-openai-function-calling?utm_source=chatgpt.com "OpenAI Function Calling vs Anthropic Tool Use: Which Is Better? – Agents Index" [3]: https://artificial-intelligence-wiki.com/agentic-ai/agent-architectures-and-components/tool-use-and-function-calling/?utm_source=chatgpt.com "Tool Use and Function Calling - Complete Guide | AI Wiki" [4]: https://www.theverge.com/news/672705/anthropic-claude-4-ai-ous-sonnet-availability?utm_source=chatgpt.com "Anthropic's Claude 4 AI models are better at coding and reasoning" [5]: https://techsy.io/blog/llm-function-calling-guide?utm_source=chatgpt.com "LLM Function Calling: The Complete Multi-Provider Guide [2026] | TECHSY" | F6: =IF(E6="","",LEN(TRIM(E6))-LEN(SUBSTITUTE(E6," ",""))+1) -> 550 | G6: Which LLM platform offers the best support for building multi-step tool-use workflows where the model decides which functions to invoke?
A7: GPT | B7: P06 | C7: Built-in Web Search | D7: 46118 | E7: If you want **built-in real-time web search that is easy to enable via API**, only a few LLM providers currently offer **native search tools** (instead of requiring you to integrate your own search API). The main ones developers use today are: | Provider | Built-in Web Search | Ease of Enabling | Accuracy | Notes | | ------------------------- | -------------------------- | ---------------- | ----------------------------- | ------------------------------- | | **Anthropic (Claude)** | ✅ Native `web_search` tool | ⭐⭐⭐⭐ Very easy | ⭐⭐⭐⭐ High | Strong agent/tool-use framework | | **Google (Gemini)** | ✅ Google Search grounding | ⭐⭐⭐ Easy | ⭐⭐⭐⭐ Very high (Google index) | Requires tool config | | **OpenAI / Azure OpenAI** | ⚠️ Preview search tools | ⭐⭐⭐ Easy | ⭐⭐⭐⭐ High | Often uses Bing grounding | | **Perplexity Sonar API** | ✅ Search-native model | ⭐⭐⭐⭐ Very easy | ⭐⭐⭐⭐⭐ Excellent | Built specifically for search | Below is a practical breakdown for building an **AI assistant with web search.** --- # 1. Anthropic Claude — easiest “native tool” integration **Best for:** agent workflows where the model decides when to search. * Anthropic provides a **built-in `web_search` tool** that you simply include in the API request. * The model automatically decides **when to search and how many times** during a response. * It returns **citations and source metadata** automatically. ([Claude API Docs][1]) Example request: ```json { "model": "claude-sonnet-4", "messages": [{"role":"user","content":"Latest news about AI chips"}], "tools": [{ "type": "web_search_20250305", "name": "web_search", "max_uses": 5 }] } ``` **Why developers like it** * Simple tool schema * Model autonomously triggers search * Works well with multi-step agent workflows **Downside** * Paid per search (~$10 per 1k searches). ([Claude API Docs][1]) --- # 2. Google Gemini — best raw search index **Best for:** factual answers and news queries. Gemini supports **Grounding with Google Search**, which connects the model directly to Google's live search results. ([Google AI for Developers][2]) Example (Python): ```python grounding_tool = types.Tool( google_search=types.GoogleSearch() ) response = client.models.generate_content( model="gemini-2.5-flash", tools=[grounding_tool] ) ``` **Advantages** * Uses Google’s search index * Built-in citation support * Works well with Google Cloud stack **Downside** * Slightly more configuration than Claude * Sometimes only returns snippets instead of full page content (a limitation some developers report). --- # 3. OpenAI / Azure OpenAI — Bing-grounded search **Best for:** Microsoft ecosystem apps. The Responses API can enable a **`web_search_preview` tool**, which grounds model outputs using **Bing Search results**. ([Microsoft Learn][3]) Key benefits: * Easy if you already use **Azure AI Foundry** * Works with the same tool-calling interface as other functions * Good for enterprise compliance But: * Still **preview in many environments** * Slightly less mature than Claude's tool-use. --- # 4. Perplexity Sonar — best search-first API **Best for:** AI assistants whose main job is answering questions from the web. Perplexity launched a **Search API that exposes its real-time web index to developers**, enabling apps to fetch current information with citations. ([The Economic Times][4]) Advantages: * Search-optimized models * High factual accuracy * Simple REST API Downside: * Smaller ecosystem compared with OpenAI/Google. --- # My recommendation (for an AI assistant) If you're building an **agent that autonomously decides when to search**, use: **🥇 Anthropic Claude + web_search tool** If your priority is **search quality from the world’s largest index**: **🥈 Google Gemini + Google Search grounding** If you want **enterprise integration with Azure**: **🥉 Azure OpenAI + Bing grounding** --- ✅ **Practical architecture used by many startups** ``` LLM (Claude / GPT / Gemini) | Tool calling | Search tool ├── Tavily / SerpAPI ├── Perplexity Search API └── Native provider search | Webpage fetch + RAG ``` This hybrid approach usually gives **better reliability than relying on a single built-in search tool.** --- 💡 **If you're building something like Zarn or a productivity assistant**, I can also show you: * The **best real-time search stack for AI agents (2026)** * A **reference architecture for LLM + search + page reader + RAG** * Which APIs cost the least per query. [1]: https://docs.anthropic.com/en/docs/agents-and-tools/tool-use/web-search-tool?utm_source=chatgpt.com "Web search tool - Anthropic" [2]: https://ai.google.dev/gemini-api/docs/google-search?utm_source=chatgpt.com "Grounding with Google Search | Gemini API | Google AI for Developers" [3]: https://learn.microsoft.com/en-us/azure/foundry/openai/how-to/web-search?utm_source=chatgpt.com "Web search with the Responses API - Microsoft Foundry | Microsoft Learn" [4]: https://m.economictimes.com/tech/artificial-intelligence/perplexity-brings-real-time-search-api-to-ai-all-you-need-to-know/articleshow/124230784.cms?utm_source=chatgpt.com "Perplexity brings real-time Search API to AI: all you need to know" | F7: =IF(E7="","",LEN(TRIM(E7))-LEN(SUBSTITUTE(E7," ",""))+1) -> 630 | G7: I am building an AI assistant that needs real-time web search capability. Which LLM provider's built-in web search tool is most accurate and easiest to enable via the API?
A8: GPT | B8: P07 | C8: Built-in Web Search | D8: 46118 | E8: If your goal is **native web-grounded answers with verifiable sources**, only a few AI platforms currently do this well. The leaders differ depending on whether you want **research-grade citations, freshest web index, or programmable APIs**. Below is the **current landscape (2025–2026)**. --- # Best AI Platforms for Native Web Search Grounding ## 1. Perplexity — Best for transparent citations **Best overall for verifiable, research-style answers** * Designed from the start as an **AI-native search engine**. * Always performs **live web retrieval** and shows **inline citations linking to sources**. * Interface encourages **click-through verification of claims**. * Offers an API (`Sonar`) for developers building grounded agents. Key strengths: * Citation-first answers * Real-time web retrieval * Multi-source synthesis * Good developer API for grounded search Evidence: Perplexity’s system retrieves live internet data and **synthesizes answers with cited sources** rather than relying only on model memory. ([Wikipedia][1]) **Best use cases** * AI research assistants * fact-checking systems * knowledge agents that must show sources --- ## 2. Google Gemini (with Search Grounding) — Best for freshest web data **Best for accessing the largest search index** * Uses **Google Search as its grounding layer** * Often the **freshest source of breaking information** * Can combine web results with **Gmail, Docs, Drive, and Maps** Advantages: * Google’s enormous search index * strong multimodal search * enterprise integrations Tradeoffs: * Citations are sometimes **less explicit or vague** * harder to audit evidence trails Gemini’s grounding works by cross-checking responses against **live Google Search results**, improving factual accuracy for current information. ([AI Tools Digest][2]) **Best use cases** * real-time news * enterprise Google Workspace workflows * location / local queries --- ## 3. OpenAI (ChatGPT Search / tool-based browsing) — Best developer ecosystem **Best balance of grounding + APIs** Capabilities: * integrated **web search tools** * structured tool-calling * streaming responses * strong SDKs Strengths: * mature developer APIs * function-calling orchestration * flexible tool use (search + other tools) Tradeoff: * citations and grounding are not always as **prominent as Perplexity’s search-first design** --- ## 4. Dedicated grounding APIs (for building agents) These are **search tools you plug into LLMs**: Examples: * **Tavily Search API** * **Brave Search API** * **SerpAPI** * **Perplexity Sonar API** They provide: * web retrieval * scraping * structured search results * citation metadata Developers often combine these with **RAG pipelines or tool-calling models**. --- # Quick comparison | Platform | Grounding Style | Source Transparency | Best For | | ----------------------------- | ----------------------- | ------------------- | -------------------- | | **Perplexity** | search-first retrieval | ⭐⭐⭐⭐ | research + citations | | **Gemini** | Google search grounding | ⭐⭐⭐ | freshest data | | **OpenAI** | tool-based browsing | ⭐⭐⭐ | developer workflows | | **Search APIs (Tavily etc.)** | external retrieval | ⭐⭐⭐⭐ | custom AI agents | --- # Recommendation for developers If you're **building an AI assistant with web grounding**: **Best stack today** Option A (easiest) * **Perplexity Sonar API** Option B (most flexible) * **GPT / Claude / Gemini + Tavily or Brave Search** Option C (Google ecosystem) * **Gemini + Vertex AI Grounding** --- ✅ **Simple rule** * **Best verifiable answers:** Perplexity * **Freshest web index:** Gemini * **Best programmable ecosystem:** OpenAI --- 💡 Since you're building **AI assistants and automation products with Azure**, I can also show you the **best architecture for web-grounded agents (LLM + search + RAG + tool use)**. That architecture is what most YC-level AI startups are using right now. [1]: https://en.wikipedia.org/wiki/Perplexity_AI?utm_source=chatgpt.com "Perplexity AI" [2]: https://www.aitoolsdigest.com/blog/best-ai-search-engines-2026?utm_source=chatgpt.com "Best AI Search Engines in 2026: Perplexity, ChatGPT Search, Gemini & More | AI Tools Digest" | F8: =IF(E8="","",LEN(TRIM(E8))-LEN(SUBSTITUTE(E8," ",""))+1) -> 509 | G8: Which AI platform offers the best native search grounding so that responses are backed by current, verifiable web sources?
A9: GPT | B9: P08 | C9: Code Execution | D9: 46118 | E9: If your goal is **“LLM writes code → executes it in a sandbox → verifies the output → returns the result”**, only a few providers currently support this natively. Below are the **best options as of 2025–2026**, ranked by reliability and developer experience. --- # 1️⃣ Anthropic (Claude) — Best Native Code Execution Tool **Provider:** Anthropic **Feature:** *Code Execution Tool* ### Why it’s currently the best * Built-in **sandbox container runtime** * Model can **write and execute code during the same API call** * Supports **Bash commands + Python** * Allows **file creation, editing, and analysis** * Useful for **data analysis, verification, and complex calculations** Key capabilities: * Runs code in **isolated containers** * **Python 3.11 environment** * Includes libraries like `numpy`, `pandas`, `scikit-learn`, `matplotlib` * **No internet access** (safer sandbox) * Container limits: ~1 CPU, 1 GB RAM, 5 GB disk * Containers expire after ~1 hour ([Claude API Docs][1]) Typical flow: 1. Model decides code execution is needed 2. Writes code 3. Sandbox runs it 4. Result returned to model 5. Model explains verified output Example API pattern: ```json { "model": "claude-opus-4-1", "messages": [{"role": "user", "content": "Compute the mean of this dataset"}], "tools": [ { "type": "code_execution_20250825", "name": "code_execution" } ] } ``` 💡 **Best use cases** * Data analysis agents * AI research assistants * financial/statistical computation * code correctness verification --- # 2️⃣ OpenAI — Mature “Code Interpreter / Python Tool” **Provider:** OpenAI OpenAI offers similar functionality through: * **Code Interpreter** * **Python tool in Assistants / Agents** * **Advanced Data Analysis** Capabilities: * Python execution * file uploads * plotting * iterative code refinement Advantages: * extremely stable * widely used ecosystem * integrated with function calling Limitations: * less customizable sandbox control than Anthropic * mostly Python (no full Bash runtime) --- # 3️⃣ Google Gemini — Execution via Tools / Colab-style Runtime **Provider:** Google Google supports code execution in: * **Gemini Advanced tools** * **Code execution environments similar to Colab** Capabilities: * Python execution * notebook-style workflows * integrated with Google Cloud Limitations: * less mature tool-use orchestration * weaker agent workflows vs OpenAI/Anthropic --- # 4️⃣ Open-Source Approach — Run Your Own Sandbox If you want **maximum control**, you can combine: * open LLM (Llama, Mistral) * container sandbox * agent framework Typical stack: ``` LLM → writes code ↓ Sandbox (Docker / Firecracker / WASM) ↓ Executor runs code ↓ Result returned to LLM ``` Popular tools: * **LangChain Code Interpreter** * **Daytona Sandbox** * **OpenCodeInterpreter frameworks** These systems integrate code generation and execution to iteratively refine results. ([arXiv][2]) --- # 🏆 Quick Recommendation | Use Case | Best Provider | | -------------------------- | -------------------------------- | | Best built-in sandbox | **Anthropic (Claude)** | | Most mature ecosystem | **OpenAI** | | Google ecosystem | **Gemini** | | Full custom infrastructure | **Open-source + Docker sandbox** | 👉 **For AI agents that verify outputs automatically:** **Anthropic’s Code Execution Tool is currently the most advanced native solution.** --- ✅ **My recommendation for your use case (agent workflows):** Use: * **Claude Sonnet or Opus + Code Execution Tool** because it enables: ``` LLM reasoning → write code → execute in sandbox → validate output → return verified answer ``` --- 💡 If you're building **a serious autonomous AI assistant**, I can also show you the **best architecture for combining:** * web search * tool calling * code execution * structured outputs (the stack used by modern AI agents). [1]: https://docs.anthropic.com/en/docs/agents-and-tools/tool-use/code-execution-tool?utm_source=chatgpt.com "Code execution tool - Anthropic" [2]: https://arxiv.org/abs/2402.14658?utm_source=chatgpt.com "OpenCodeInterpreter: Integrating Code Generation with Execution and Refinement" | F9: =IF(E9="","",LEN(TRIM(E9))-LEN(SUBSTITUTE(E9," ",""))+1) -> 475 | G9: I need an LLM that can execute code in a sandboxed environment to verify outputs before returning them. Which provider offers the best code execution tool?
A10: GPT | B10: P09 | C10: Code Execution | D10: 46118 | E10: For **Python-based data analysis where the model writes and runs code**, only a few AI platforms offer a **true code interpreter / sandbox execution environment**. The best options depend on reliability, Python ecosystem support (pandas, numpy, matplotlib), and API maturity. Below are the **top platforms currently used for this use case**. --- # 1️⃣ OpenAI — Best Overall for Data Analysis **Platform:** OpenAI **Tool:** Code Interpreter (Responses API) **Why it’s widely considered the best:** * Runs **Python in a fully sandboxed container** * Supports **data science libraries** (pandas, numpy, matplotlib) * Handles **file uploads and outputs** * Can **iterate on failing code automatically** * Produces **charts, CSVs, and processed datasets** The model writes Python, executes it in a container, and returns the result (tables, plots, files). ([OpenAI Platform][1]) ### Key capabilities * Upload datasets (CSV, Excel, JSON) * Generate charts * Clean/transform data * Perform statistical analysis * Export files ### Example workflow User query: ``` Analyze this CSV and show revenue trends. ``` Model actions: 1. Writes Python code 2. Runs it in sandbox 3. Generates plot 4. Returns chart + explanation ### Strengths ✔ Best runtime stability ✔ Mature API ✔ Handles large datasets well ✔ Automatic code iteration ### Weakness * Code execution sessions cost extra --- # 2️⃣ Anthropic — Strong Alternative **Platform:** Anthropic **Tool:** Claude Code Interpreter Anthropic also supports **sandboxed Python execution**, where the model runs code and returns files or results. Key feature: * **State persists across turns**, so code variables can be reused later in the conversation. ([Dartantic AI Documentation][2]) Example workflow: ``` Step 1: Load dataset and compute summary Step 2: Plot histogram Step 3: Export CSV ``` Claude can continue working with the same Python environment. ### Strengths ✔ Large context window ✔ Persistent runtime state ✔ Excellent reasoning ### Weakness * Slightly less mature tooling ecosystem --- # 3️⃣ Self-Hosted Code Interpreter (Best for Full Control) If you want **maximum flexibility**, you can run your own interpreter. Examples: * **LLM Sandbox** * **Docker-based execution frameworks** * **WASM Python runtimes** These run LLM-generated code inside **isolated containers** to protect the host system. ([GitHub][3]) ### Strengths ✔ Full control ✔ Can install any Python library ✔ No vendor lock-in ### Weakness * Requires infrastructure and security hardening --- # 📊 Quick Comparison | Platform | Python Execution | File Handling | Best Use | | -------------------------- | ---------------- | ------------- | --------------------------- | | OpenAI Code Interpreter | ⭐⭐⭐⭐ | ⭐⭐⭐⭐ | Data science & analytics | | Anthropic Code Interpreter | ⭐⭐⭐⭐ | ⭐⭐⭐ | Agent workflows | | Self-hosted sandbox | ⭐⭐⭐⭐⭐ | ⭐⭐⭐⭐⭐ | Custom enterprise pipelines | --- # 🏆 Recommendation For **data analysis tasks specifically**, the best platform today is: **1️⃣ OpenAI Code Interpreter** because it provides: * reliable Python execution * built-in data science tooling * easy API integration * strong chart and file output support. --- ✅ **Rule of thumb** * **Data analysis app → OpenAI** * **Agent workflows with long context → Anthropic** * **Custom enterprise execution → Self-hosted sandbox** --- 💡 Since you're building AI systems and backend workflows, I can also show you **the architecture used by production AI apps (like ChatGPT Advanced Data Analysis)** to run Python safely at scale. [1]: https://platform.openai.com/docs/guides/tools-code-interpreter/?utm_source=chatgpt.com "Code Interpreter | OpenAI API" [2]: https://docs.dartantic.ai/server-side-tools/anthropic-code-interpreter?utm_source=chatgpt.com "Anthropic Code Interpreter - Dartantic AI Documentation" [3]: https://github.com/vndee/llm-sandbox?utm_source=chatgpt.com "GitHub - vndee/llm-sandbox: Lightweight and portable LLM sandbox runtime (code interpreter) Python library." | F10: =IF(E10="","",LEN(TRIM(E10))-LEN(SUBSTITUTE(E10," ",""))+1) -> 476 | G10: Which AI platform's code interpreter is most suitable for data analysis tasks involving Python, where the model runs code and returns results?
A11: GPT | B11: P10 | C11: Agentic CLI Tools | D11: 46118 | E11: If you want a **terminal-native, agentic coding assistant that can read, write, and execute code locally**, a few tools dominate in 2025–2026. The best option depends on whether you want **maximum autonomy, model flexibility, or ecosystem stability**. Below are the **top CLI AI coding agents** used by developers today. --- # 🧠 Best Terminal-Native Agentic Coding Assistants ## 1️⃣ OpenAI — **Codex CLI** **Best overall terminal agent** * Runs directly in your terminal. * Can **read files, modify code, and execute shell commands**. * Has multiple autonomy modes: * Suggest (safe) * Auto-edit * Full auto (agent executes commands in sandbox). ([OpenAI Help Center][1]) * Works across your **entire repository**, iteratively fixing errors and rerunning tasks. * Designed specifically for **agentic coding workflows**. **Key strengths** * True **read → edit → run → iterate loop** * Git integration * Sandbox execution environment * Lightweight install (`npm install -g @openai/codex`) ([OpenAI Help Center][1]) **Example usage** ```bash codex "Fix failing tests in this repo" codex "Add Stripe payment endpoint" codex "Refactor authentication module" ``` 👉 If you want a **CLI agent similar to AutoGPT but for coding**, this is the cleanest option. --- ## 2️⃣ Anthropic — **Claude Code** **Best raw coding intelligence** A **terminal-first coding agent** powered by Claude models. Capabilities: * Reads entire codebases * Writes multi-file patches * Runs commands * Handles Git workflows * Supports multi-agent execution Claude models can process extremely large contexts (up to ~1M tokens), letting the tool analyze tens of thousands of lines of code at once. ([NxCode][2]) **Best for** * Large repos * refactors * complex reasoning tasks * security audits Downside: * Works only with Claude models. --- ## 3️⃣ Aider **Best open-source multi-model CLI** Aider has been a favorite among terminal developers for a long time. Key features: * Works with **OpenAI, Claude, Gemini, etc** * Git-aware edits * Multi-file patches * Chat-driven refactoring Unlike Codex CLI, it’s **model-agnostic**, so you can switch providers easily. ([Vibe Coding][3]) **Example** ```bash aider app.py ``` Then: ``` Add JWT authentication ``` It edits the repo and commits the change. --- ## 4️⃣ Google — **Gemini CLI** Google recently introduced **Gemini CLI**, a terminal agent that lets developers interact with Gemini models from the command line for coding and automation tasks. ([The Verge][4]) Capabilities include: * natural language coding commands * integration with Google tools * very high request limits in preview Still early compared with Codex / Claude Code. --- # 🏆 Quick Comparison | Tool | Provider | Strength | Best For | | --------------- | ----------- | ------------------------- | --------------------------- | | **Codex CLI** | OpenAI | Most balanced agentic CLI | Autonomous coding workflows | | **Claude Code** | Anthropic | Strongest reasoning | Large codebases | | **Aider** | Open-source | Model flexibility | power users / custom stacks | | **Gemini CLI** | Google | large context + ecosystem | Google stack | --- # ⭐ My Practical Recommendation For a **terminal-native agentic coding assistant in 2026**: **1️⃣ Best overall:** ➡️ **Codex CLI** **2️⃣ Best coding intelligence:** ➡️ **Claude Code** **3️⃣ Best open-source flexibility:** ➡️ **Aider** --- ✅ **Typical workflow used by advanced devs** Many developers actually run: * **Codex CLI or Claude Code** for autonomous coding * **Aider** for quick commits / patches This gives you both **agent automation + flexible model switching**. --- 💡 Since you're building AI-heavy products (like Zarnite), I can also show you **how to build your own terminal coding agent** using: * OpenAI tools * local execution sandbox * repo editing loop That’s basically how **Cursor / Claude Code agents are built internally**. [1]: https://help.openai.com/en/articles/11096431?utm_source=chatgpt.com "OpenAI Codex CLI – Getting Started | OpenAI Help Center" [2]: https://www.nxcode.io/resources/news/best-ai-for-coding-2026-tools-ranked?utm_source=chatgpt.com "Best AI Coding Tools 2026: Complete Ranking by Real-World Performance | NxCode" [3]: https://vibecoding.app/blog/openai-codex-cli-vs-aider?utm_source=chatgpt.com "OpenAI Codex CLI vs. Aider: The Terminal War" [4]: https://www.theverge.com/news/692517/google-gemini-cli-ai-agent-dev-terminal?utm_source=chatgpt.com "Google is bringing Gemini CLI to developers' terminals" | F11: =IF(E11="","",LEN(TRIM(E11))-LEN(SUBSTITUTE(E11," ",""))+1) -> 546 | G11: want a terminal-native agentic coding assistant that can read, write, and execute code directly in my local development environment. Which AI provider offers the best CLI tool for this?
A12: GPT | B12: P11 | C12: Agentic CLI Tools | D12: 46120 | E12: For autonomous software development from the terminal** (e.g., refactoring a codebase, writing tests, running commands, and iterating until builds pass), a small set of **agentic CLI tools from major AI labs dominate the space**. The two strongest are from **Anthropic and OpenAI**, with a few strong open-source alternatives. Below is a practical comparison of the **best command-line AI coding agents** today. --- # Best AI Command-Line Coding Agents (2026) | AI Company | CLI Tool | Strengths | Best Use Case | | ----------------------- | --------------------- | ---------------------------------------------------------- | ------------------------------------- | | **Anthropic** | Claude Code | Best autonomous reasoning and large-codebase understanding | Complex refactors, full project tasks | | **OpenAI** | Codex CLI | Open-source, strong execution tools and sandboxing | Dev workflows needing customization | | **Aider (open source)** | Aider CLI | Git-native coding agent with multi-model support | Lightweight iterative development | | **Cursor (agent mode)** | Cursor CLI/IDE hybrid | Powerful agent workflows but tied to IDE | Full-stack dev with visual debugging | --- # 1. Anthropic — Claude Code (Best for Autonomous Software Engineering) **Claude Code** is widely considered the **most capable terminal coding agent right now**. Key capabilities: * Reads **entire codebases** with large context windows * Performs **multi-file edits automatically** * Runs shell commands and tests * Uses **multi-agent coordination** for complex tasks * Can manage **Git workflows** (commit, branch, review) Performance highlights: * Achieved **~72.7% accuracy on SWE-bench Verified**, outperforming competing CLI agents in complex engineering tasks. ([blog.openreplay.com][1]) * Uses models optimized for software engineering like **Claude Opus**, which can maintain context across large projects. ([mightybot.ai][2]) Example workflow: ``` claude-code "Refactor the authentication module to use JWT and write unit tests" ``` The agent will: 1. Scan the codebase 2. Plan refactoring 3. Edit multiple files 4. Run tests 5. Fix failures 6. Commit changes Best for: * Large repos * Automated refactors * Test generation * Multi-step engineering tasks --- # 2. OpenAI — Codex CLI (Best Open Ecosystem Agent) **Codex CLI** is OpenAI’s official **terminal coding agent** built in Rust and powered by GPT-5-Codex models. Key capabilities: * Reads and edits local files * Executes shell commands * Built-in **sandboxed execution environment** * Natural-language instructions → code changes * Works with multiple OpenAI reasoning models Example: ``` codex "find and fix the memory leak in the worker pool" ``` Strengths: * **Open source** and extensible * Deep integration with OpenAI models * Strong debugging and reasoning capabilities Trade-off: * Slightly weaker than Claude on complex SWE benchmarks, but **more customizable** and cheaper. ([blog.openreplay.com][1]) Best for: * Engineering teams * Developers wanting control over the agent * Custom toolchains --- # 3. Aider (Best Lightweight Terminal Agent) **Aider** is an open-source CLI tool that integrates with models like GPT-4/5 or Claude. Capabilities: * Direct Git integration * Automatically edits files suggested by the model * Supports multi-file edits and commit workflows Typical usage: ``` aider main.py /refactor authentication logic ``` Advantages: * Extremely simple * Works with many model providers * Great for **iterative coding loops** Limitations: * Less autonomous than Claude Code * Requires more human guidance --- # 4. Cursor Agent (IDE + CLI Hybrid) Cursor is technically an **AI IDE**, but its **Agent mode** behaves like a coding agent capable of: * Planning multi-step tasks * Editing multiple files * Running builds/tests * Iterating until tasks succeed However, it is **not purely terminal-native**, which is why many backend engineers still prefer CLI tools. --- # Bottom Line If your goal is **autonomous software development from the terminal**, the current ranking is roughly: 1️⃣ **Anthropic — Claude Code** Best for fully autonomous tasks like refactoring entire modules or generating test suites. 2️⃣ **OpenAI — Codex CLI** Best open ecosystem CLI agent with strong reasoning and execution. 3️⃣ **Aider** Best lightweight open-source coding assistant. --- ✅ **Simple recommendation** * **Most powerful autonomous CLI agent:** Claude Code * **Most customizable/open CLI agent:** Codex CLI * **Best lightweight dev workflow:** Aider --- 💡 **Important insight for founders/devs:** The most advanced teams now run **multi-agent coding pipelines** (e.g., Claude writes code, Codex reviews/tests it). This dramatically improves reliability for autonomous development. --- If you want, I can also show you: * **The top 7 AI coding agents used by YC startups** * **How to build your own autonomous coding agent using LLM tools (AutoDev style)**. [1]: https://blog.openreplay.com/openai-codex-vs-claude-code-cli-ai-tool/?utm_source=chatgpt.com "OpenAI Codex vs. Claude Code: Which CLI AI tool is best for coding?" [2]: https://www.mightybot.ai/blog/coding-ai-agents-for-accelerating-engineering-workflows?utm_source=chatgpt.com "Mighty Blog - 9 Best AI Coding Agents in 2026, Ranked" | F12: =IF(E12="","",LEN(TRIM(E12))-LEN(SUBSTITUTE(E12," ",""))+1) -> 643 | G12: Which AI company's command-line coding agent is best suited for autonomous software development tasks such as refactoring a codebase or writing tests?
A13: GPT | B13: P12 | C13: IDE integration | D13: 46120 | E13: For a **modern AI-assisted coding workflow** (editing a repo, running tests, refactoring code, generating PRs, etc.), the main contenders right now are **OpenAI Codex**, **Anthropic Claude Code**, and **Google Gemini Code Assist / Gemini CLI**. They all work, but they optimize for **different developer experiences** depending on how you work (IDE-centric vs terminal-native vs lightweight autocomplete). Below is a clear breakdown of **developer experience + IDE integration**, especially for **VS Code and JetBrains**. --- # 1. Claude Code (Anthropic) ## Developer experience **Best for:** large codebases, architectural reasoning, autonomous refactors. Claude Code is designed as a **terminal-first coding agent** that can read an entire repo, run tests, edit files, and interact with git. It behaves more like a **junior developer working in your repo** than a simple autocomplete tool. ([Dinitha Wickramasinghe Portfolio][1]) Key strengths: * Deep **repo-level reasoning** * Multi-file refactors * Built-in **Git workflows (branching, commits, PR generation)** * Runs tests and iterates automatically * Supports **background agents for parallel tasks** It also has a **very large context window (~200k tokens)** which helps when working with big projects. ([Dinitha Wickramasinghe Portfolio][1]) --- ## IDE integration **VS Code:** Excellent **JetBrains:** Excellent Claude Code works with both major ecosystems and is currently one of the **few AI coding agents with strong support for JetBrains IDEs**. ([Heurekadevs][2]) Typical workflow: ``` Terminal: claude plan refactor authentication system Claude: - analyzes repo - edits multiple files - runs tests - commits changes ``` Developers often run Claude Code **alongside VS Code/JetBrains rather than replacing them.** --- # 2. OpenAI Codex (ChatGPT Codex / Codex CLI) ## Developer experience **Best for:** productivity and implementation speed. Codex focuses on **practical code generation and implementation tasks**, often producing production-ready code quickly. ([Tom's Guide][3]) Strengths: * Very strong **code generation accuracy** * Great for **writing features quickly** * Multi-agent workflows via ChatGPT * Can run tests and tools in cloud environments Compared to Claude: * Slightly less architectural reasoning * Often **faster at writing functional code** Some developers treat Codex as a **“workhorse coder”** while other tools handle planning. ([Tom's Guide][3]) --- ## IDE integration **VS Code:** Excellent **JetBrains:** Good Codex integrates well through: * ChatGPT integrations * VS Code extensions * GitHub workflows and PR automation GitHub has also begun integrating **Codex agents directly into GitHub and VS Code**, enabling AI-driven pull requests and issue workflows. ([TechRadar][4]) --- # 3. Gemini Code Assist / Gemini CLI (Google) ## Developer experience **Best for:** lightweight assistance and IDE-native coding. Gemini Code Assist focuses more on **traditional IDE assistance** (similar to Copilot) rather than autonomous coding agents. Strengths: * Fast inline completions * Clean refactoring suggestions * Large context window * Strong free tier However, for **complex multi-file tasks**, it tends to lag behind Claude or Codex. ([Termdock][5]) --- ## IDE integration **VS Code:** Excellent **JetBrains:** Limited / partial Gemini Code Assist currently prioritizes **VS Code integration**, with JetBrains support still more limited. ([Heurekadevs][2]) Workflow style: ``` IDE-centric workflow prompt → suggestion → approve diff ``` Google emphasizes **developer approval of each change** via diffs inside the editor. ([Heurekadevs][2]) --- # Comparison — Developer Experience | Feature | Claude Code | OpenAI Codex | Gemini Code Assist | | --------------------- | ------------------------ | ------------------ | ------------------ | | Primary workflow | Terminal agent | Hybrid agent + IDE | IDE assistant | | Multi-file refactors | Excellent | Good | Moderate | | Repo-scale reasoning | Excellent | Good | Limited | | Autonomous tasks | Very strong | Strong | Moderate | | Code generation speed | Good | Excellent | Good | | Context window | Very large | Large | Very large | | Best for | Architecture & refactors | Implementation | Inline coding | --- # IDE Integration Comparison | IDE | Claude Code | Codex | Gemini Code Assist | | ------------------ | ----------- | --------- | ------------------ | | VS Code | Excellent | Excellent | Excellent | | JetBrains | Excellent | Good | Limited | | Terminal workflows | Excellent | Excellent | Good | | Git integration | Excellent | Strong | Moderate | --- # Real-World Developer Setup (Common in 2026) Many advanced developers now **use multiple coding agents simultaneously**: Example workflow: 1️⃣ **Claude Code** * Understand codebase * Plan architecture * Design refactors 2️⃣ **Codex** * Implement features quickly * Write tests * Generate PRs 3️⃣ **Gemini** * Inline suggestions * Code review * quick refactors This “multi-agent coding” setup is becoming common in high-productivity workflows. ([Termdock][5]) --- # My Recommendation (for your workflow) Since you mentioned **VS Code + JetBrains** and working on real products: **Best developer experience overall** 🥇 **Claude Code** Best repo understanding + JetBrains support. **Best productivity coder** 🥈 **Codex** **Best IDE autocomplete** 🥉 **Gemini Code Assist** --- ✅ **Best single tool today:** Claude Code ⚡ **Best combo:** Claude Code + Codex --- 💡 If you'd like, I can also show you **the current “elite developer stack” in 2026** (Cursor, Codex, Claude Code, MCP tools, etc.) that many startup engineers are using to get **10× productivity**. [1]: https://www.dinithaw.com/blogs/chatgpt-codex-vs-claude-code-vs-gemini-cli?utm_source=chatgpt.com "ChatGPT Codex vs Claude Code vs Gemini CLI: An Unbiased Developer Comparison | Dinitha Wickramasinghe Blog" [2]: https://www.heurekadevs.com/gemini-code-assist-vs-claude-code-2025-ai-coding-assistants-compared?utm_source=chatgpt.com "Gemini Code Assist vs Claude Code: 2025 AI Coding Assistants Compared | Heurekadevs" [3]: https://www.tomsguide.com/ai/claude-code-vs-chatgpt-codex-which-ai-coding-agent-is-actually-better?utm_source=chatgpt.com "Claude Code vs ChatGPT Codex: Which AI coding agent is actually better?" [4]: https://www.techradar.com/pro/github-integrates-claude-and-codex-ai-coding-agents-directly-into-github?utm_source=chatgpt.com "GitHub integrates Claude and Codex AI coding agents directly into GitHub" [5]: https://www.termdock.com/en/blog/claude-code-vs-codex-cli?utm_source=chatgpt.com "Claude Code vs Codex CLI: 2026 Comparison | Termdock" | F13: =IF(E13="","",LEN(TRIM(E13))-LEN(SUBSTITUTE(E13," ",""))+1) -> 782 | G13: Which platforms (e.g., Codex, Claude Code, Gemini Code Assist) offer the best developer experience for this workflow, and how well do they integrate with VS Code and JetBrains?
